Workbook

Sheet Candidate
A1: CandidateID | B1: CandidateName | C1: Email | D1: Gender | E1: Major | F1: EducationLevel | G1: ExperienceYears | H1: Notice_Period | I1: City
A2: C001 | B2: Kenny Ackermann 001 | C2: kenny@gmail.com | D2: M | E2: Computer Science | F2: Bachelor | G2: 5 | H2: 1 | I2: Paradis
A3: C002 | B3: Kenny Ackermann 002 | C3: kenny@gmail.com | D3: F | E3: Accounting | F3: Bachelor | G3: 4 | H3: 2 | I3: Paradis
A4: C003 | B4: Kenny Ackermann 003 | C4: kenny@gmail.com | D4: F | E4: Computer Science | F4: Bachelor | G4: 5 | H4: 1 | I4: Paradis
A5: C004 | B5: Kenny Ackermann 004 | C5: kenny@gmail.com | D5: M | E5: Fiscal Management | F5: Master | G5: 5 | H5: 1 | I5: Paradis
A6: C005 | B6: Kenny Ackermann 005 | C6: kenny@gmail.com | D6: M | E6: Data Science | F6: Bachelor | G6: 5 | H6: 1 | I6: Paradis
A7: C006 | B7: Kenny Ackermann 006 | C7: kenny@gmail.com | D7: F | E7: Accounting | F7: Bachelor | G7: 5 | H7: 1 | I7: Paradis
A8: C007 | B8: Kenny Ackermann 007 | C8: kenny@gmail.com | D8: M | E8: Computer Science | F8: Bachelor | G8: 6 | H8: 1 | I8: Paradis
A9: C008 | B9: Kenny Ackermann 008 | C9: kenny@gmail.com | D9: F | E9: Fiscal Management | F9: Master | G9: 2 | H9: 1 | I9: Paradis
A10: C009 | B10: Kenny Ackermann 009 | C10: kenny@gmail.com | D10: M | E10: Data Science | F10: Bachelor | G10: 5 | H10: 1 | I10: Paradis
A11: C010 | B11: Kenny Ackermann 010 | C11: kenny@gmail.com | D11: M | E11: Computer Science | F11: Bachelor | G11: 4 | H11: 1 | I11: Paradis
A12: C011 | B12: Kenny Ackermann 011 | C12: kenny@gmail.com | D12: M | E12: Computer Science | F12: Bachelor | G12: 5 | H12: 1 | I12: Paradis
A13: C012 | B13: Kenny Ackermann 012 | C13: kenny@gmail.com | D13: M | E13: Fiscal Management | F13: Bachelor | G13: 2 | H13: 1 | I13: Paradis
... A76: BC005 | B76: Sakura Hyuga | C76: sakura@gmail.com | D76: F | E76: Law | F76: Bachelor | G76: 2 | H76: 1 | I76: Konoha

Sheet Job
A1: JobID | B1: JobTitle | C1: Department | D1: HiringManager | E1: EmploymentType | F1: OpenDate | G1: CloseDate | H1: TargetHeadCount | I1: JobStatus | J1: SalaryAllocation | K1: EmployeeLevel
A2: J001 | B2: Data Analyst | C2: IT | D2: Levi Ackermann | E2: Full-Time | F2: 46223 | G2: 46233 | H2: 1 | I2: Closed | J2: 15000000 | K2: GG03
A3: J002 | B3: Data Engineer | C3: IT | D3: Mikasa Ackermann | E3: Full-Time | F3: 46174 | H3: 1 | I3: Open | J3: 18000000 | K3: GG03
A4: J003 | B4: Data Scientist | C4: IT | D4: Jean Kirsctein | E4: Full-Time | F4: 46174 | H4: 1 | I4: Open | J4: 20000000 | K4: GG03
A5: J004 | B5: Automation Engineer | C5: IT | D5: Historia Flower | E5: Full-Time | F5: 46174 | H5: 1 | I5: Open | J5: 21000000 | K5: GG03
A6: J005 | B6: Finance Analyst | C6: Finance | D6: Armin Artlet | E6: Full-Time | F6: 46174 | H6: 1 | I6: Open | J6: 12000000 | K6: GG02
A7: J006 | B7: General Affair | C7: HR | D7: Eren Yeager | E7: Full-Time | F7: 46174 | H7: 1 | I7: Open | J7: 12000000 | K7: GG02
A8: J007 | B8: QA Engineer | C8: IT | D8: Hange Zoe | E8: Full-Time | F8: 46174 | H8: 1 | I8: Open | J8: 17000000 | K8: GG03
A9: J008 | B9: Tax Associate | C9: Finance | D9: Erwin Smith | E9: Full-Time | F9: 46174 | H9: 1 | I9: Open | J9: 3200000 | K9: GG01
A10: J009 | B10: Payroll Analyst | C10: HR | D10: Sasha Blouse | E10: Full-Time | F10: 46174 | H10: 1 | I10: On Hold | J10: 8000000 | K10: GG01
A11: J010 | B11: Finance Manager | C11: Finance | D11: Sashi Bleeese | E11: Full-Time | F11: 46175 | H11: 1 | I11: Open | J11: 30000000 | K11: GG07
A12: J011 | B12: Tax Executive | C12: Finance | D12: Connie | E12: Full-Time | F12: 46175 | H12: 1 | I12: Open | J12: 15000000 | K12: GG03
A13: J012 | B13: Accounting Associate | C13: Finance | D13: Jean Mere | E13: Full-Time | F13: 46175 | H13: 1 | I13: Open | J13: 8000000 | K13: GG02
A14: J013 | B14: Accounting Executive | C14: Finance | D14: Erland Halaand | E14: Full-Time | F14: 46175 | H14: 1 | I14: Open | J14: 15000000 | K14: GG03
... A19: J018 | B19: HR Business Partner | C19: HR | D19: Sashi Bleeese | E19: Full-Time | F19: 46175 | H19: 1 | I19: Open | J19: 14000000 | K19: GG03
A20: J019 | B20: Data Engineer Manager | C20: IT | D20: Needy Man | E20: Full-Time | F20: 46143 | G20: 46205 | H20: 1 | I20: Closed | J20: 35000000 | K20: GG07
A21: J020 | B21: Legal Manager | C21: Legal | D21: Justin Andersen | E21: Full-Time | F21: 46113 | G21: 46218 | H21: 1 | I21: Closed | J21: 40000000 | K21: GG08

Sheet Application
A1: ApplicationID | B1: CandidateID | C1: JobID | D1: ApplicationDate | E1: SourceID | F1: CurrentStatus | G1: FinalOutcome | H1: InterviewerID
A2: A001 | B2: C010 | C2: J001 | D2: 46233 | E2: S01 | F2: Hired | G2: Hired
A3: A002 | B3: C010 | C3: J002 | D3: 46205 | E3: S02 | F3: Applied
A4: A003 | B4: C014 | C4: J005 | D4: 46204 | E4: S01 | F4: Applied
A5: A004 | B5: C003 | C5: J003 | D5: 46204 | E5: S01 | F5: Applied
A6: A005 | B6: C007 | C6: J003 | D6: 46204 | E6: S01 | F6: Screening
A7: A006 | B7: C007 | C7: J002 | D7: 46204 | E7: S01 | F7: Applied
A8: A007 | B8: C010 | C8: J007 | D8: 46204 | E8: S01 | F8: Applied
A9: A008 | B9: C011 | C9: J003 | D9: 46204 | E9: S01 | F9: Applied
A10: A009 | B10: C015 | C10: J003 | D10: 46174 | E10: S01 | F10: Screening
A11: A010 | B11: C019 | C11: J001 | D11: 46191 | E11: S01 | F11: Interview 2
A12: A011 | B12: C023 | C12: J004 | D12: 46192 | E12: S01 | F12: Applied
A13: A012 | B13: C023 | C13: J001 | D13: 46194 | E13: S01 | F13: Applied
A14: A013 | B14: C027 | C14: J001 | D14: 46174 | E14: S01 | F14: Screening
... A69: A068 | B69: C028 | C69: J017 | D69: 46181 | E69: S02 | F69: Screening
A70: A069 | B70: C038 | C70: J017 | D70: 46182 | E70: S02 | F70: Rejected | G70: =F70 -> Rejected
A71: A070 | B71: C046 | C71: J015 | D71: 46183 | E71: S02 | F71: Screening
A72: A071 | B72: C062 | C72: J015 | D72: 46184 | E72: S02 | F72: Screening
A73: A072 | B73: C004 | C73: J014 | D73: 46192 | E73: S02 | F73: Applied
A74: A073 | B74: C016 | C74: J018 | D74: 46193 | E74: S02 | F74: Rejected | G74: =F74 -> Rejected
A75: A074 | B75: C020 | C75: J018 | D75: 46194 | E75: S02 | F75: Applied
A76: A075 | B76: C024 | C76: J014 | D76: 46195 | E76: S01 | F76: Applied
A77: A076 | B77: C032 | C77: J014 | D77: 46196 | E77: S01 | F77: Applied
A78: A077 | B78: C042 | C78: J018 | D78: 46197 | E78: S01 | F78: Rejected | G78: =F78 -> Rejected
A79: A078 | B79: C050 | C79: J014 | D79: 46198 | E79: S01 | F79: Applied
A80: A079 | B80: C054 | C80: J018 | D80: 46199 | E80: S02 | F80: Applied
A81: A080 | B81: C058 | C81: J018 | D81: 46200 | E81: S02 | F81: Rejected | G81: =F81 -> Rejected
A82: A081 | B82: C066 | C82: J018 | D82: 46201 | E82: S02 | F82: Rejected | G82: =F82 -> Rejected
A83: A088 | B83: C069 | C83: J019 | D83: 46205 | E83: S02 | F83: Hired | G83: Hired
A84: A089 | B84: C070 | C84: J009 | D84: 46233 | E84: S01 | F84: Hired | G84: Hired
A85: A090 | B85: BC001 | C85: J020 | D85: 46114 | E85: S04 | F85: Rejected | G85: Rejected
A86: A091 | B86: BC002 | C86: J020 | D86: 46156 | E86: S04 | F86: Rejected | G86: Rejected
A87: A092 | B87: BC003 | C87: J020 | D87: 46157 | E87: S03 | F87: Hired | G87: Hired
A88: A093 | B88: BC003 | C88: J020 | D88: 46128 | E88: S04 | F88: Screening
A89: A094 | B89: BC003 | C89: J020 | D89: 46159 | E89: S04 | F89: Screening

Sheet StatusHistory
A1: ApplicationID | B1: Status | C1: StatusDate | D1: PIC_ID
A2: A069 | B2: Applied | C2: 46182
A3: A069 | B3: Screening | C3: 46182
A4: A069 | B4: Rejected | C4: 46182
A5: A073 | B5: Applied | C5: 46193
A6: A073 | B6: Screening | C6: 46194
A7: A073 | B7: Interview 1 | C7: 46200 | D7: HR001
A8: A073 | B8: Rejected | C8: 46211
A9: A077 | B9: Applied | C9: 46197
A10: A077 | B10: Screening | C10: 46197
A11: A077 | B11: Interview 1 | C11: 46205 | D11: HR003
A12: A077 | B12: Rejected | C12: 46211
A13: A080 | B13: Applied | C13: 46200
A14: A080 | B14: Screening | C14: 46203
A15: A080 | B15: Rejected | C15: 46204
A16: A081 | B16: Applied | C16: 46201
A17: A081 | B17: Screening | C17: 46203
A18: A081 | B18: Rejected | C18: 46203
A19: A001 | B19: Applied | C19: 46204
A20: A001 | B20: Screening | C20: 46205
A21: A001 | B21: Interview 1 | C21: 46211 | D21: HR002
A22: A001 | B22: Interview 2 | C22: 46218 | D22: U003
A23: A001 | B23: Interview 3 | C23: 46227 | D23: U008
A24: A001 | B24: Offered | C24: 46231 | D24: HR002
A25: A001 | B25: Hired | C25: 46233 | D25: HR002
A26: A010 | B26: Applied | C26: 46178
A27: A010 | B27: Screening | C27: 46179
A28: A010 | B28: Interview 1 | C28: 46185 | D28: HR001
A29: A010 | B29: Interview 2 | C29: 46191 | D29: U004
A30: A015 | B30: Applied | C30: 46174
A31: A015 | B31: Screening | C31: 46175
A32: A015 | B32: Interview 1 | C32: 46183 | D32: HR002
A33: A021 | B33: Applied | C33: 46175
A34: A021 | B34: Screening | C34: 46176
A35: A021 | B35: Interview 1 | C35: 46183 | D35: HR003
A36: A024 | B36: Applied | C36: 46178
A37: A024 | B37: Screening | C37: 46179
A38: A024 | B38: Interview 1 | C38: 46187 | D38: HR004
A39: A024 | B39: Interview 2 | C39: 46193 | D39: U001
A40: A050 | B40: Applied | C40: 46179
...

Sheet Source
A1: SourceID | B1: Source
A2: S01 | B2: LinkedIn
A3: S02 | B3: JobStreet
A4: S03 | B4: Referral
A5: S04 | B5: Company Website
A6: S05 | B6: Other
A7: S06 | B7: Indeed
A8: S07 | B8: Kalibrr

Sheet Interview
A1: InterviewerID | B1: Name | C1: Category
A2: HR002 | B2: Rei Hino | C2: HR
A3: HR001 | B3: Chooper | C3: HR
A4: HR003 | B4: Sanji | C4: HR
A5: HR004 | B5: Izuku Midoriya | C5: HR
A6: U001 | B6: Katsuki | C6: User
A7: U002 | B7: Uraraka | C7: User
A8: U003 | B8: Tenya | C8: User
A9: U004 | B9: Ida | C9: User
A10: U005 | B10: Mikasa | C10: User
A11: U006 | B11: Yachi | C11: User
A12: U007 | B12: Kageyama | C12: User
... A22: U012 | B22: Justin Andersen | C22: User
